{"content": {"suites": {"0": {"status": {"total_pass": 1, "total_skip": 0, "total_xpass": 0, "total_xfail": 0, "total_rerun": 0, "total_fail": 4, "total_error": 9}, "tests": {"0": {"status": "ERROR", "message": "monkeypatch = <_pytest.monkeypatch.MonkeyPatch object at 0x107ed0590>\nmock_session = <test_crawl4ai_extended.MockClientSession object at 0x107ed24d0>\n\n    @pytest.fixture\n    async def crawl4ai_backend(monkeypatch, mock_session):\n        config = Crawl4AIConfig(\n            max_retries=2,\n            timeout=10.0,\n            headers={\"User-Agent\": \"Test/1.0\"},\n            rate_limit=0.1,  # Fast rate limit for testing\n            max_depth=3,\n            concurrent_requests=2\n        )\n        backend = Crawl4AIBackend(config=config)\n    \n        # Patch the session creation\n        async def mock_create_session():\n            return mock_session\n    \n>       monkeypatch.setattr(backend, \"_create_session\", mock_create_session)\nE       AttributeError: <src.backends.crawl4ai.Crawl4AIBackend object at 0x107e1a710> has no attribute '_create_session'\n\ntests/test_crawl4ai_extended.py:98: AttributeError\n", "test_name": "test_crawl_with_urlinfo", "rerun": "0"}, "1": {"status": "ERROR", "message": "monkeypatch = <_pytest.monkeypatch.MonkeyPatch object at 0x107ec7f90>\nmock_session = <test_crawl4ai_extended.MockClientSession object at 0x107ec5250>\n\n    @pytest.fixture\n    async def crawl4ai_backend(monkeypatch, mock_session):\n        config = Crawl4AIConfig(\n            max_retries=2,\n            timeout=10.0,\n            headers={\"User-Agent\": \"Test/1.0\"},\n            rate_limit=0.1,  # Fast rate limit for testing\n            max_depth=3,\n            concurrent_requests=2\n        )\n        backend = Crawl4AIBackend(config=config)\n    \n        # Patch the session creation\n        async def mock_create_session():\n            return mock_session\n    \n>       monkeypatch.setattr(backend, \"_create_session\", mock_create_session)\nE       AttributeError: <src.backends.crawl4ai.Crawl4AIBackend object at 0x107ec5950> has no attribute '_create_session'\n\ntests/test_crawl4ai_extended.py:98: AttributeError\n", "test_name": "test_crawl_depth_first", "rerun": "0"}, "2": {"status": "ERROR", "message": "monkeypatch = <_pytest.monkeypatch.MonkeyPatch object at 0x107f012d0>\nmock_session = <test_crawl4ai_extended.MockClientSession object at 0x107f03b10>\n\n    @pytest.fixture\n    async def crawl4ai_backend(monkeypatch, mock_session):\n        config = Crawl4AIConfig(\n            max_retries=2,\n            timeout=10.0,\n            headers={\"User-Agent\": \"Test/1.0\"},\n            rate_limit=0.1,  # Fast rate limit for testing\n            max_depth=3,\n            concurrent_requests=2\n        )\n        backend = Crawl4AIBackend(config=config)\n    \n        # Patch the session creation\n        async def mock_create_session():\n            return mock_session\n    \n>       monkeypatch.setattr(backend, \"_create_session\", mock_create_session)\nE       AttributeError: <src.backends.crawl4ai.Crawl4AIBackend object at 0x107f03690> has no attribute '_create_session'\n\ntests/test_crawl4ai_extended.py:98: AttributeError\n", "test_name": "test_rate_limiting_precision", "rerun": "0"}, "3": {"status": "ERROR", "message": "monkeypatch = <_pytest.monkeypatch.MonkeyPatch object at 0x107ed3290>\nmock_session = <test_crawl4ai_extended.MockClientSession object at 0x107ec7ed0>\n\n    @pytest.fixture\n    async def crawl4ai_backend(monkeypatch, mock_session):\n        config = Crawl4AIConfig(\n            max_retries=2,\n            timeout=10.0,\n            headers={\"User-Agent\": \"Test/1.0\"},\n            rate_limit=0.1,  # Fast rate limit for testing\n            max_depth=3,\n            concurrent_requests=2\n        )\n        backend = Crawl4AIBackend(config=config)\n    \n        # Patch the session creation\n        async def mock_create_session():\n            return mock_session\n    \n>       monkeypatch.setattr(backend, \"_create_session\", mock_create_session)\nE       AttributeError: <src.backends.crawl4ai.Crawl4AIBackend object at 0x107ec5c10> has no attribute '_create_session'\n\ntests/test_crawl4ai_extended.py:98: AttributeError\n", "test_name": "test_concurrent_request_limit", "rerun": "0"}, "4": {"status": "ERROR", "message": "monkeypatch = <_pytest.monkeypatch.MonkeyPatch object at 0x107f28450>\nmock_session = <test_crawl4ai_extended.MockClientSession object at 0x107f28bd0>\n\n    @pytest.fixture\n    async def crawl4ai_backend(monkeypatch, mock_session):\n        config = Crawl4AIConfig(\n            max_retries=2,\n            timeout=10.0,\n            headers={\"User-Agent\": \"Test/1.0\"},\n            rate_limit=0.1,  # Fast rate limit for testing\n            max_depth=3,\n            concurrent_requests=2\n        )\n        backend = Crawl4AIBackend(config=config)\n    \n        # Patch the session creation\n        async def mock_create_session():\n            return mock_session\n    \n>       monkeypatch.setattr(backend, \"_create_session\", mock_create_session)\nE       AttributeError: <src.backends.crawl4ai.Crawl4AIBackend object at 0x107f28590> has no attribute '_create_session'\n\ntests/test_crawl4ai_extended.py:98: AttributeError\n", "test_name": "test_url_normalization", "rerun": "0"}, "5": {"status": "ERROR", "message": "monkeypatch = <_pytest.monkeypatch.MonkeyPatch object at 0x107f24a50>\nmock_session = <test_crawl4ai_extended.MockClientSession object at 0x107f24d10>\n\n    @pytest.fixture\n    async def crawl4ai_backend(monkeypatch, mock_session):\n        config = Crawl4AIConfig(\n            max_retries=2,\n            timeout=10.0,\n            headers={\"User-Agent\": \"Test/1.0\"},\n            rate_limit=0.1,  # Fast rate limit for testing\n            max_depth=3,\n            concurrent_requests=2\n        )\n        backend = Crawl4AIBackend(config=config)\n    \n        # Patch the session creation\n        async def mock_create_session():\n            return mock_session\n    \n>       monkeypatch.setattr(backend, \"_create_session\", mock_create_session)\nE       AttributeError: <src.backends.crawl4ai.Crawl4AIBackend object at 0x107f25750> has no attribute '_create_session'\n\ntests/test_crawl4ai_extended.py:98: AttributeError\n", "test_name": "test_error_propagation", "rerun": "0"}, "6": {"status": "ERROR", "message": "monkeypatch = <_pytest.monkeypatch.MonkeyPatch object at 0x107ed2e50>\nmock_session = <test_crawl4ai_extended.MockClientSession object at 0x107e85050>\n\n    @pytest.fixture\n    async def crawl4ai_backend(monkeypatch, mock_session):\n        config = Crawl4AIConfig(\n            max_retries=2,\n            timeout=10.0,\n            headers={\"User-Agent\": \"Test/1.0\"},\n            rate_limit=0.1,  # Fast rate limit for testing\n            max_depth=3,\n            concurrent_requests=2\n        )\n        backend = Crawl4AIBackend(config=config)\n    \n        # Patch the session creation\n        async def mock_create_session():\n            return mock_session\n    \n>       monkeypatch.setattr(backend, \"_create_session\", mock_create_session)\nE       AttributeError: <src.backends.crawl4ai.Crawl4AIBackend object at 0x107e86290> has no attribute '_create_session'\n\ntests/test_crawl4ai_extended.py:98: AttributeError\n", "test_name": "test_retry_behavior", "rerun": "0"}, "7": {"status": "ERROR", "message": "monkeypatch = <_pytest.monkeypatch.MonkeyPatch object at 0x107f5e550>\nmock_session = <test_crawl4ai_extended.MockClientSession object at 0x107f5e710>\n\n    @pytest.fixture\n    async def crawl4ai_backend(monkeypatch, mock_session):\n        config = Crawl4AIConfig(\n            max_retries=2,\n            timeout=10.0,\n            headers={\"User-Agent\": \"Test/1.0\"},\n            rate_limit=0.1,  # Fast rate limit for testing\n            max_depth=3,\n            concurrent_requests=2\n        )\n        backend = Crawl4AIBackend(config=config)\n    \n        # Patch the session creation\n        async def mock_create_session():\n            return mock_session\n    \n>       monkeypatch.setattr(backend, \"_create_session\", mock_create_session)\nE       AttributeError: <src.backends.crawl4ai.Crawl4AIBackend object at 0x107f5ec10> has no attribute '_create_session'\n\ntests/test_crawl4ai_extended.py:98: AttributeError\n", "test_name": "test_metrics_accuracy", "rerun": "0"}, "8": {"status": "ERROR", "message": "monkeypatch = <_pytest.monkeypatch.MonkeyPatch object at 0x107f783d0>\nmock_session = <test_crawl4ai_extended.MockClientSession object at 0x107f79290>\n\n    @pytest.fixture\n    async def crawl4ai_backend(monkeypatch, mock_session):\n        config = Crawl4AIConfig(\n            max_retries=2,\n            timeout=10.0,\n            headers={\"User-Agent\": \"Test/1.0\"},\n            rate_limit=0.1,  # Fast rate limit for testing\n            max_depth=3,\n            concurrent_requests=2\n        )\n        backend = Crawl4AIBackend(config=config)\n    \n        # Patch the session creation\n        async def mock_create_session():\n            return mock_session\n    \n>       monkeypatch.setattr(backend, \"_create_session\", mock_create_session)\nE       AttributeError: <src.backends.crawl4ai.Crawl4AIBackend object at 0x107f7a710> has no attribute '_create_session'\n\ntests/test_crawl4ai_extended.py:98: AttributeError\n", "test_name": "test_resource_cleanup", "rerun": "0"}, "9": {"status": "FAIL", "message": "   AssertionError: assert 'https://docs.python.org/3' == 'https://docs.python.org/3/'\n     \n     - https://docs.python.org/3/\n     ?                          -\n     + https://docs.python.org/3\n", "test_name": "test_url_info_initialization[https://docs.python.org/3/-expected0]", "rerun": "0"}, "10": {"status": "PASS", "message": "", "test_name": "test_url_info_initialization[https://docs.python.org-expected1]", "rerun": "0"}, "11": {"status": "FAIL", "message": "   AssertionError: assert 'http:///invalid-url' == 'invalid-url'\n     \n     - invalid-url\n     + http:///invalid-url\n", "test_name": "test_url_info_initialization[invalid-url-expected2]", "rerun": "0"}, "12": {"status": "FAIL", "message": "   AssertionError: assert 1 == 2\n    +  where 1 = len({URLInfo(original='https://docs.python.org/3/', normalized='https://docs.python.org/3', scheme='https', netloc='docs.python.org', path='/3', is_valid=True)})\n", "test_name": "test_url_info_hashable", "rerun": "0"}, "13": {"status": "FAIL", "message": "   Failed: DID NOT RAISE <class 'Exception'>\n", "test_name": "test_url_info_immutable", "rerun": "0"}}, "suite_name": "tests/test_crawl4ai_extended.py"}}}, "date": "November 26, 2024", "start_time": 1732618230.584461, "total_suite": 1, "status": "FAIL", "status_list": {"pass": "1", "fail": "4", "skip": "0", "error": "9", "xpass": "0", "xfail": "0", "rerun": "0"}, "total_tests": "14"}